[2024-10-08T11:25:53.763+0000] {local_task_job_runner.py:123} INFO - ::group::Pre task execution logs
[2024-10-08T11:25:53.773+0000] {taskinstance.py:2612} INFO - Dependencies all met for dep_context=non-requeueable deps ti=<TaskInstance: trigger_dag.wait_for_run_file manual__2024-10-08T11:25:52.669249+00:00 [queued]>
[2024-10-08T11:25:53.777+0000] {taskinstance.py:2612} INFO - Dependencies all met for dep_context=requeueable deps ti=<TaskInstance: trigger_dag.wait_for_run_file manual__2024-10-08T11:25:52.669249+00:00 [queued]>
[2024-10-08T11:25:53.777+0000] {taskinstance.py:2865} INFO - Starting attempt 1 of 1
[2024-10-08T11:25:53.782+0000] {taskinstance.py:2888} INFO - Executing <Task(FileSensor): wait_for_run_file> on 2024-10-08 11:25:52.669249+00:00
[2024-10-08T11:25:53.786+0000] {warnings.py:112} WARNING - /home/airflow/.local/lib/python3.12/site-packages/airflow/task/task_runner/standard_task_runner.py:70: DeprecationWarning: This process (pid=445) is multi-threaded, use of fork() may lead to deadlocks in the child.
  pid = os.fork()

[2024-10-08T11:25:53.786+0000] {standard_task_runner.py:72} INFO - Started process 447 to run task
[2024-10-08T11:25:53.787+0000] {standard_task_runner.py:104} INFO - Running: ['airflow', 'tasks', 'run', 'trigger_dag', 'wait_for_run_file', 'manual__2024-10-08T11:25:52.669249+00:00', '--job-id', '245', '--raw', '--subdir', 'DAGS_FOLDER/trigger_dag.py', '--cfg-path', '/tmp/tmpywxxa6e5']
[2024-10-08T11:25:53.788+0000] {standard_task_runner.py:105} INFO - Job 245: Subtask wait_for_run_file
[2024-10-08T11:25:53.817+0000] {task_command.py:467} INFO - Running <TaskInstance: trigger_dag.wait_for_run_file manual__2024-10-08T11:25:52.669249+00:00 [running]> on host 99c9ec34a420
[2024-10-08T11:25:53.864+0000] {taskinstance.py:3131} INFO - Exporting env vars: AIRFLOW_CTX_DAG_OWNER='airflow' AIRFLOW_CTX_DAG_ID='trigger_dag' AIRFLOW_CTX_TASK_ID='wait_for_run_file' AIRFLOW_CTX_EXECUTION_DATE='2024-10-08T11:25:52.669249+00:00' AIRFLOW_CTX_TRY_NUMBER='1' AIRFLOW_CTX_DAG_RUN_ID='manual__2024-10-08T11:25:52.669249+00:00'
[2024-10-08T11:25:53.865+0000] {logging_mixin.py:190} INFO - Task instance is in running state
[2024-10-08T11:25:53.866+0000] {logging_mixin.py:190} INFO -  Previous state of the Task instance: queued
[2024-10-08T11:25:53.866+0000] {logging_mixin.py:190} INFO - Current task name:wait_for_run_file state:running start_date:2024-10-08 11:25:53.773622+00:00
[2024-10-08T11:25:53.866+0000] {logging_mixin.py:190} INFO - Dag name:trigger_dag and current dag run status:running
[2024-10-08T11:25:53.866+0000] {taskinstance.py:731} INFO - ::endgroup::
[2024-10-08T11:25:53.866+0000] {baseoperator.py:405} WARNING - FileSensor.execute cannot be called outside TaskInstance!
[2024-10-08T11:25:53.872+0000] {base.py:84} INFO - Retrieving connection 'fs_default'
[2024-10-08T11:25:53.873+0000] {filesystem.py:109} INFO - Poking for file /opt/airflow/data/small_text.txt
[2024-10-08T11:26:53.876+0000] {filesystem.py:109} INFO - Poking for file /opt/airflow/data/small_text.txt
[2024-10-08T11:27:53.884+0000] {filesystem.py:109} INFO - Poking for file /opt/airflow/data/small_text.txt
[2024-10-08T11:28:53.895+0000] {filesystem.py:109} INFO - Poking for file /opt/airflow/data/small_text.txt
[2024-10-08T11:29:00.428+0000] {local_task_job_runner.py:346} WARNING - State of this instance has been externally set to None. Terminating instance.
[2024-10-08T11:29:00.429+0000] {local_task_job_runner.py:245} INFO - ::endgroup::
[2024-10-08T11:29:00.430+0000] {process_utils.py:132} INFO - Sending 15 to group 447. PIDs of all processes in the group: [447]
[2024-10-08T11:29:00.431+0000] {process_utils.py:87} INFO - Sending the signal 15 to group 447
[2024-10-08T11:29:00.431+0000] {taskinstance.py:3092} ERROR - Received SIGTERM. Terminating subprocesses.
[2024-10-08T11:29:00.446+0000] {taskinstance.py:3310} ERROR - Task failed with exception
Traceback (most recent call last):
  File "/home/airflow/.local/lib/python3.12/site-packages/airflow/models/taskinstance.py", line 767, in _execute_task
    result = _execute_callable(context=context, **execute_callable_kwargs)
             ^^^^^^^^^^^^^^^^^^^^^^^^^^^^^^^^^^^^^^^^^^^^^^^^^^^^^^^^^^^^^
  File "/home/airflow/.local/lib/python3.12/site-packages/airflow/models/taskinstance.py", line 733, in _execute_callable
    return ExecutionCallableRunner(
           ^^^^^^^^^^^^^^^^^^^^^^^^
  File "/home/airflow/.local/lib/python3.12/site-packages/airflow/utils/operator_helpers.py", line 252, in run
    return self.func(*args, **kwargs)
           ^^^^^^^^^^^^^^^^^^^^^^^^^^
  File "/home/airflow/.local/lib/python3.12/site-packages/airflow/models/baseoperator.py", line 406, in wrapper
    return func(self, *args, **kwargs)
           ^^^^^^^^^^^^^^^^^^^^^^^^^^^
  File "/home/airflow/.local/lib/python3.12/site-packages/airflow/sensors/filesystem.py", line 123, in execute
    super().execute(context=context)
  File "/home/airflow/.local/lib/python3.12/site-packages/airflow/models/baseoperator.py", line 406, in wrapper
    return func(self, *args, **kwargs)
           ^^^^^^^^^^^^^^^^^^^^^^^^^^^
  File "/home/airflow/.local/lib/python3.12/site-packages/airflow/sensors/base.py", line 334, in execute
    time.sleep(self._get_next_poke_interval(started_at, run_duration, poke_count))
  File "/home/airflow/.local/lib/python3.12/site-packages/airflow/models/taskinstance.py", line 3094, in signal_handler
    raise AirflowTaskTerminated("Task received SIGTERM signal")
airflow.exceptions.AirflowTaskTerminated: Task received SIGTERM signal
[2024-10-08T11:29:00.454+0000] {logging_mixin.py:190} INFO - Task instance in failure state
[2024-10-08T11:29:00.455+0000] {logging_mixin.py:190} INFO - Task start:2024-10-08 11:25:53.773622+00:00 end:2024-10-08 11:29:00.451963+00:00 duration:186.678341
[2024-10-08T11:29:00.455+0000] {logging_mixin.py:190} INFO - Task:<Task(FileSensor): wait_for_run_file> dag:<DAG: trigger_dag> dagrun:<DagRun trigger_dag @ 2024-10-08 11:25:52.669249+00:00: manual__2024-10-08T11:25:52.669249+00:00, state:running, queued_at: 2024-10-08 11:25:52.681337+00:00. externally triggered: True>
[2024-10-08T11:29:00.456+0000] {logging_mixin.py:190} INFO - Failure caused by Task received SIGTERM signal
[2024-10-08T11:29:00.456+0000] {taskinstance.py:1225} INFO - Marking task as FAILED. dag_id=trigger_dag, task_id=wait_for_run_file, run_id=manual__2024-10-08T11:25:52.669249+00:00, execution_date=20241008T112552, start_date=20241008T112553, end_date=20241008T112900
[2024-10-08T11:29:00.473+0000] {taskinstance.py:340} INFO - ::group::Post task execution logs
[2024-10-08T11:29:00.474+0000] {standard_task_runner.py:124} ERROR - Failed to execute job 245 for task wait_for_run_file ((psycopg2.errors.ForeignKeyViolation) insert or update on table "task_fail" violates foreign key constraint "task_fail_ti_fkey"
DETAIL:  Key (dag_id, task_id, run_id, map_index)=(trigger_dag, wait_for_run_file, manual__2024-10-08T11:25:52.669249+00:00, -1) is not present in table "task_instance".

[SQL: INSERT INTO task_fail (task_id, dag_id, run_id, map_index, start_date, end_date, duration) VALUES (%(task_id)s, %(dag_id)s, %(run_id)s, %(map_index)s, %(start_date)s, %(end_date)s, %(duration)s) RETURNING task_fail.id]
[parameters: {'task_id': 'wait_for_run_file', 'dag_id': 'trigger_dag', 'run_id': 'manual__2024-10-08T11:25:52.669249+00:00', 'map_index': -1, 'start_date': datetime.datetime(2024, 10, 8, 11, 25, 53, 773622, tzinfo=Timezone('UTC')), 'end_date': datetime.datetime(2024, 10, 8, 11, 29, 0, 451963, tzinfo=Timezone('UTC')), 'duration': 186}]
(Background on this error at: https://sqlalche.me/e/14/gkpj); 447)
Traceback (most recent call last):
  File "/home/airflow/.local/lib/python3.12/site-packages/airflow/models/taskinstance.py", line 273, in _run_raw_task
    TaskInstance._execute_task_with_callbacks(
  File "/home/airflow/.local/lib/python3.12/site-packages/airflow/models/taskinstance.py", line 3158, in _execute_task_with_callbacks
    result = self._execute_task(context, task_orig)
             ^^^^^^^^^^^^^^^^^^^^^^^^^^^^^^^^^^^^^^
  File "/home/airflow/.local/lib/python3.12/site-packages/airflow/models/taskinstance.py", line 3182, in _execute_task
    return _execute_task(self, context, task_orig)
           ^^^^^^^^^^^^^^^^^^^^^^^^^^^^^^^^^^^^^^^
  File "/home/airflow/.local/lib/python3.12/site-packages/airflow/models/taskinstance.py", line 767, in _execute_task
    result = _execute_callable(context=context, **execute_callable_kwargs)
             ^^^^^^^^^^^^^^^^^^^^^^^^^^^^^^^^^^^^^^^^^^^^^^^^^^^^^^^^^^^^^
  File "/home/airflow/.local/lib/python3.12/site-packages/airflow/models/taskinstance.py", line 733, in _execute_callable
    return ExecutionCallableRunner(
           ^^^^^^^^^^^^^^^^^^^^^^^^
  File "/home/airflow/.local/lib/python3.12/site-packages/airflow/utils/operator_helpers.py", line 252, in run
    return self.func(*args, **kwargs)
           ^^^^^^^^^^^^^^^^^^^^^^^^^^
  File "/home/airflow/.local/lib/python3.12/site-packages/airflow/models/baseoperator.py", line 406, in wrapper
    return func(self, *args, **kwargs)
           ^^^^^^^^^^^^^^^^^^^^^^^^^^^
  File "/home/airflow/.local/lib/python3.12/site-packages/airflow/sensors/filesystem.py", line 123, in execute
    super().execute(context=context)
  File "/home/airflow/.local/lib/python3.12/site-packages/airflow/models/baseoperator.py", line 406, in wrapper
    return func(self, *args, **kwargs)
           ^^^^^^^^^^^^^^^^^^^^^^^^^^^
  File "/home/airflow/.local/lib/python3.12/site-packages/airflow/sensors/base.py", line 334, in execute
    time.sleep(self._get_next_poke_interval(started_at, run_duration, poke_count))
  File "/home/airflow/.local/lib/python3.12/site-packages/airflow/models/taskinstance.py", line 3094, in signal_handler
    raise AirflowTaskTerminated("Task received SIGTERM signal")
airflow.exceptions.AirflowTaskTerminated: Task received SIGTERM signal

During handling of the above exception, another exception occurred:

Traceback (most recent call last):
  File "/home/airflow/.local/lib/python3.12/site-packages/sqlalchemy/engine/base.py", line 1910, in _execute_context
    self.dialect.do_execute(
  File "/home/airflow/.local/lib/python3.12/site-packages/sqlalchemy/engine/default.py", line 736, in do_execute
    cursor.execute(statement, parameters)
psycopg2.errors.ForeignKeyViolation: insert or update on table "task_fail" violates foreign key constraint "task_fail_ti_fkey"
DETAIL:  Key (dag_id, task_id, run_id, map_index)=(trigger_dag, wait_for_run_file, manual__2024-10-08T11:25:52.669249+00:00, -1) is not present in table "task_instance".


The above exception was the direct cause of the following exception:

Traceback (most recent call last):
  File "/home/airflow/.local/lib/python3.12/site-packages/airflow/task/task_runner/standard_task_runner.py", line 117, in _start_by_fork
    ret = args.func(args, dag=self.dag)
          ^^^^^^^^^^^^^^^^^^^^^^^^^^^^^
  File "/home/airflow/.local/lib/python3.12/site-packages/airflow/cli/cli_config.py", line 49, in command
    return func(*args, **kwargs)
           ^^^^^^^^^^^^^^^^^^^^^
  File "/home/airflow/.local/lib/python3.12/site-packages/airflow/utils/cli.py", line 115, in wrapper
    return f(*args, **kwargs)
           ^^^^^^^^^^^^^^^^^^
  File "/home/airflow/.local/lib/python3.12/site-packages/airflow/cli/commands/task_command.py", line 483, in task_run
    task_return_code = _run_task_by_selected_method(args, _dag, ti)
                       ^^^^^^^^^^^^^^^^^^^^^^^^^^^^^^^^^^^^^^^^^^^^
  File "/home/airflow/.local/lib/python3.12/site-packages/airflow/cli/commands/task_command.py", line 256, in _run_task_by_selected_method
    return _run_raw_task(args, ti)
           ^^^^^^^^^^^^^^^^^^^^^^^
  File "/home/airflow/.local/lib/python3.12/site-packages/airflow/cli/commands/task_command.py", line 341, in _run_raw_task
    return ti._run_raw_task(
           ^^^^^^^^^^^^^^^^^
  File "/home/airflow/.local/lib/python3.12/site-packages/airflow/utils/session.py", line 97, in wrapper
    return func(*args, session=session, **kwargs)
           ^^^^^^^^^^^^^^^^^^^^^^^^^^^^^^^^^^^^^^
  File "/home/airflow/.local/lib/python3.12/site-packages/airflow/models/taskinstance.py", line 3004, in _run_raw_task
    return _run_raw_task(
           ^^^^^^^^^^^^^^
  File "/home/airflow/.local/lib/python3.12/site-packages/airflow/models/taskinstance.py", line 327, in _run_raw_task
    ti.handle_failure(e, test_mode, context, session=session)
  File "/home/airflow/.local/lib/python3.12/site-packages/airflow/utils/session.py", line 94, in wrapper
    return func(*args, **kwargs)
           ^^^^^^^^^^^^^^^^^^^^^
  File "/home/airflow/.local/lib/python3.12/site-packages/airflow/models/taskinstance.py", line 3427, in handle_failure
    _handle_failure(
  File "/home/airflow/.local/lib/python3.12/site-packages/airflow/utils/session.py", line 94, in wrapper
    return func(*args, **kwargs)
           ^^^^^^^^^^^^^^^^^^^^^
  File "/home/airflow/.local/lib/python3.12/site-packages/airflow/api_internal/internal_api_call.py", line 139, in wrapper
    return func(*args, **kwargs)
           ^^^^^^^^^^^^^^^^^^^^^
  File "/home/airflow/.local/lib/python3.12/site-packages/airflow/models/taskinstance.py", line 1243, in _handle_failure
    TaskInstance.save_to_db(failure_context["ti"], session)
  File "/home/airflow/.local/lib/python3.12/site-packages/airflow/api_internal/internal_api_call.py", line 139, in wrapper
    return func(*args, **kwargs)
           ^^^^^^^^^^^^^^^^^^^^^
  File "/home/airflow/.local/lib/python3.12/site-packages/airflow/utils/session.py", line 94, in wrapper
    return func(*args, **kwargs)
           ^^^^^^^^^^^^^^^^^^^^^
  File "/home/airflow/.local/lib/python3.12/site-packages/airflow/models/taskinstance.py", line 3399, in save_to_db
    session.flush()
  File "/home/airflow/.local/lib/python3.12/site-packages/sqlalchemy/orm/session.py", line 3449, in flush
    self._flush(objects)
  File "/home/airflow/.local/lib/python3.12/site-packages/sqlalchemy/orm/session.py", line 3588, in _flush
    with util.safe_reraise():
         ^^^^^^^^^^^^^^^^^^^
  File "/home/airflow/.local/lib/python3.12/site-packages/sqlalchemy/util/langhelpers.py", line 70, in __exit__
    compat.raise_(
  File "/home/airflow/.local/lib/python3.12/site-packages/sqlalchemy/util/compat.py", line 211, in raise_
    raise exception
  File "/home/airflow/.local/lib/python3.12/site-packages/sqlalchemy/orm/session.py", line 3549, in _flush
    flush_context.execute()
  File "/home/airflow/.local/lib/python3.12/site-packages/sqlalchemy/orm/unitofwork.py", line 456, in execute
    rec.execute(self)
  File "/home/airflow/.local/lib/python3.12/site-packages/sqlalchemy/orm/unitofwork.py", line 630, in execute
    util.preloaded.orm_persistence.save_obj(
  File "/home/airflow/.local/lib/python3.12/site-packages/sqlalchemy/orm/persistence.py", line 245, in save_obj
    _emit_insert_statements(
  File "/home/airflow/.local/lib/python3.12/site-packages/sqlalchemy/orm/persistence.py", line 1238, in _emit_insert_statements
    result = connection._execute_20(
             ^^^^^^^^^^^^^^^^^^^^^^^
  File "/home/airflow/.local/lib/python3.12/site-packages/sqlalchemy/engine/base.py", line 1710, in _execute_20
    return meth(self, args_10style, kwargs_10style, execution_options)
           ^^^^^^^^^^^^^^^^^^^^^^^^^^^^^^^^^^^^^^^^^^^^^^^^^^^^^^^^^^^
  File "/home/airflow/.local/lib/python3.12/site-packages/sqlalchemy/sql/elements.py", line 334, in _execute_on_connection
    return connection._execute_clauseelement(
           ^^^^^^^^^^^^^^^^^^^^^^^^^^^^^^^^^^
  File "/home/airflow/.local/lib/python3.12/site-packages/sqlalchemy/engine/base.py", line 1577, in _execute_clauseelement
    ret = self._execute_context(
          ^^^^^^^^^^^^^^^^^^^^^^
  File "/home/airflow/.local/lib/python3.12/site-packages/sqlalchemy/engine/base.py", line 1953, in _execute_context
    self._handle_dbapi_exception(
  File "/home/airflow/.local/lib/python3.12/site-packages/sqlalchemy/engine/base.py", line 2134, in _handle_dbapi_exception
    util.raise_(
  File "/home/airflow/.local/lib/python3.12/site-packages/sqlalchemy/util/compat.py", line 211, in raise_
    raise exception
  File "/home/airflow/.local/lib/python3.12/site-packages/sqlalchemy/engine/base.py", line 1910, in _execute_context
    self.dialect.do_execute(
  File "/home/airflow/.local/lib/python3.12/site-packages/sqlalchemy/engine/default.py", line 736, in do_execute
    cursor.execute(statement, parameters)
sqlalchemy.exc.IntegrityError: (psycopg2.errors.ForeignKeyViolation) insert or update on table "task_fail" violates foreign key constraint "task_fail_ti_fkey"
DETAIL:  Key (dag_id, task_id, run_id, map_index)=(trigger_dag, wait_for_run_file, manual__2024-10-08T11:25:52.669249+00:00, -1) is not present in table "task_instance".

[SQL: INSERT INTO task_fail (task_id, dag_id, run_id, map_index, start_date, end_date, duration) VALUES (%(task_id)s, %(dag_id)s, %(run_id)s, %(map_index)s, %(start_date)s, %(end_date)s, %(duration)s) RETURNING task_fail.id]
[parameters: {'task_id': 'wait_for_run_file', 'dag_id': 'trigger_dag', 'run_id': 'manual__2024-10-08T11:25:52.669249+00:00', 'map_index': -1, 'start_date': datetime.datetime(2024, 10, 8, 11, 25, 53, 773622, tzinfo=Timezone('UTC')), 'end_date': datetime.datetime(2024, 10, 8, 11, 29, 0, 451963, tzinfo=Timezone('UTC')), 'duration': 186}]
(Background on this error at: https://sqlalche.me/e/14/gkpj)
[2024-10-08T11:29:00.532+0000] {process_utils.py:80} INFO - Process psutil.Process(pid=447, status='terminated', exitcode=1, started='11:25:53') (447) terminated with exit code 1
