[2024-10-07T12:57:32.522+0000] {local_task_job_runner.py:123} INFO - ::group::Pre task execution logs
[2024-10-07T12:57:32.534+0000] {taskinstance.py:2612} INFO - Dependencies all met for dep_context=non-requeueable deps ti=<TaskInstance: sql_dag.insert_new_row manual__2024-10-07T12:57:27.461984+00:00 [queued]>
[2024-10-07T12:57:32.538+0000] {taskinstance.py:2612} INFO - Dependencies all met for dep_context=requeueable deps ti=<TaskInstance: sql_dag.insert_new_row manual__2024-10-07T12:57:27.461984+00:00 [queued]>
[2024-10-07T12:57:32.538+0000] {taskinstance.py:2865} INFO - Starting attempt 1 of 1
[2024-10-07T12:57:32.545+0000] {taskinstance.py:2888} INFO - Executing <Task(SQLExecuteQueryOperator): insert_new_row> on 2024-10-07 12:57:27.461984+00:00
[2024-10-07T12:57:32.548+0000] {warnings.py:112} WARNING - /home/airflow/.local/lib/python3.12/site-packages/airflow/task/task_runner/standard_task_runner.py:70: DeprecationWarning: This process (pid=3626) is multi-threaded, use of fork() may lead to deadlocks in the child.
  pid = os.fork()

[2024-10-07T12:57:32.548+0000] {standard_task_runner.py:72} INFO - Started process 3628 to run task
[2024-10-07T12:57:32.549+0000] {standard_task_runner.py:104} INFO - Running: ['airflow', 'tasks', 'run', 'sql_dag', 'insert_new_row', 'manual__2024-10-07T12:57:27.461984+00:00', '--job-id', '176', '--raw', '--subdir', 'DAGS_FOLDER/sql.py', '--cfg-path', '/tmp/tmpdw8x9mtw']
[2024-10-07T12:57:32.549+0000] {standard_task_runner.py:105} INFO - Job 176: Subtask insert_new_row
[2024-10-07T12:57:32.580+0000] {task_command.py:467} INFO - Running <TaskInstance: sql_dag.insert_new_row manual__2024-10-07T12:57:27.461984+00:00 [running]> on host ea4b7cb1f1d7
[2024-10-07T12:57:32.630+0000] {taskinstance.py:3131} INFO - Exporting env vars: AIRFLOW_CTX_DAG_OWNER='airflow' AIRFLOW_CTX_DAG_ID='sql_dag' AIRFLOW_CTX_TASK_ID='insert_new_row' AIRFLOW_CTX_EXECUTION_DATE='2024-10-07T12:57:27.461984+00:00' AIRFLOW_CTX_TRY_NUMBER='1' AIRFLOW_CTX_DAG_RUN_ID='manual__2024-10-07T12:57:27.461984+00:00'
[2024-10-07T12:57:32.632+0000] {logging_mixin.py:190} INFO - Task instance is in running state
[2024-10-07T12:57:32.632+0000] {logging_mixin.py:190} INFO -  Previous state of the Task instance: queued
[2024-10-07T12:57:32.632+0000] {logging_mixin.py:190} INFO - Current task name:insert_new_row state:running start_date:2024-10-07 12:57:32.534513+00:00
[2024-10-07T12:57:32.632+0000] {logging_mixin.py:190} INFO - Dag name:sql_dag and current dag run status:running
[2024-10-07T12:57:32.632+0000] {taskinstance.py:731} INFO - ::endgroup::
[2024-10-07T12:57:32.633+0000] {sql.py:266} INFO - Executing: INSERT INTO table_name VALUES(%s, %s, %s);
[2024-10-07T12:57:32.638+0000] {base.py:84} INFO - Retrieving connection 'postgres_default'
[2024-10-07T12:57:32.645+0000] {base.py:84} INFO - Retrieving connection 'postgres_default'
[2024-10-07T12:57:32.649+0000] {sql.py:509} INFO - Running statement: INSERT INTO table_name VALUES(%s, %s, %s);, parameters: (7537535, '1ac8a4d459', datetime.datetime(2024, 10, 7, 12, 57, 32, 161863))
[2024-10-07T12:57:32.650+0000] {taskinstance.py:3310} ERROR - Task failed with exception
Traceback (most recent call last):
  File "/home/airflow/.local/lib/python3.12/site-packages/airflow/models/taskinstance.py", line 767, in _execute_task
    result = _execute_callable(context=context, **execute_callable_kwargs)
             ^^^^^^^^^^^^^^^^^^^^^^^^^^^^^^^^^^^^^^^^^^^^^^^^^^^^^^^^^^^^^
  File "/home/airflow/.local/lib/python3.12/site-packages/airflow/models/taskinstance.py", line 733, in _execute_callable
    return ExecutionCallableRunner(
           ^^^^^^^^^^^^^^^^^^^^^^^^
  File "/home/airflow/.local/lib/python3.12/site-packages/airflow/utils/operator_helpers.py", line 252, in run
    return self.func(*args, **kwargs)
           ^^^^^^^^^^^^^^^^^^^^^^^^^^
  File "/home/airflow/.local/lib/python3.12/site-packages/airflow/models/baseoperator.py", line 406, in wrapper
    return func(self, *args, **kwargs)
           ^^^^^^^^^^^^^^^^^^^^^^^^^^^
  File "/home/airflow/.local/lib/python3.12/site-packages/airflow/providers/common/sql/operators/sql.py", line 272, in execute
    output = hook.run(
             ^^^^^^^^^
  File "/home/airflow/.local/lib/python3.12/site-packages/airflow/providers/common/sql/hooks/sql.py", line 456, in run
    self._run_command(cur, sql_statement, parameters)
  File "/home/airflow/.local/lib/python3.12/site-packages/airflow/providers/common/sql/hooks/sql.py", line 512, in _run_command
    cur.execute(sql_statement, parameters)
psycopg2.errors.UndefinedTable: relation "table_name" does not exist
LINE 1: INSERT INTO table_name VALUES(7537535, '1ac8a4d459', '2024-1...
                    ^

[2024-10-07T12:57:32.658+0000] {logging_mixin.py:190} INFO - Task instance in failure state
[2024-10-07T12:57:32.658+0000] {logging_mixin.py:190} INFO - Task start:2024-10-07 12:57:32.534513+00:00 end:2024-10-07 12:57:32.657766+00:00 duration:0.123253
[2024-10-07T12:57:32.658+0000] {logging_mixin.py:190} INFO - Task:<Task(SQLExecuteQueryOperator): insert_new_row> dag:<DAG: sql_dag> dagrun:<DagRun sql_dag @ 2024-10-07 12:57:27.461984+00:00: manual__2024-10-07T12:57:27.461984+00:00, state:running, queued_at: 2024-10-07 12:57:27.474871+00:00. externally triggered: True>
[2024-10-07T12:57:32.658+0000] {logging_mixin.py:190} INFO - Failure caused by relation "table_name" does not exist
LINE 1: INSERT INTO table_name VALUES(7537535, '1ac8a4d459', '2024-1...
                    ^
[2024-10-07T12:57:32.659+0000] {taskinstance.py:1225} INFO - Marking task as FAILED. dag_id=sql_dag, task_id=insert_new_row, run_id=manual__2024-10-07T12:57:27.461984+00:00, execution_date=20241007T125727, start_date=20241007T125732, end_date=20241007T125732
[2024-10-07T12:57:32.666+0000] {taskinstance.py:340} INFO - ::group::Post task execution logs
[2024-10-07T12:57:32.666+0000] {standard_task_runner.py:124} ERROR - Failed to execute job 176 for task insert_new_row (relation "table_name" does not exist
LINE 1: INSERT INTO table_name VALUES(7537535, '1ac8a4d459', '2024-1...
                    ^
; 3628)
Traceback (most recent call last):
  File "/home/airflow/.local/lib/python3.12/site-packages/airflow/task/task_runner/standard_task_runner.py", line 117, in _start_by_fork
    ret = args.func(args, dag=self.dag)
          ^^^^^^^^^^^^^^^^^^^^^^^^^^^^^
  File "/home/airflow/.local/lib/python3.12/site-packages/airflow/cli/cli_config.py", line 49, in command
    return func(*args, **kwargs)
           ^^^^^^^^^^^^^^^^^^^^^
  File "/home/airflow/.local/lib/python3.12/site-packages/airflow/utils/cli.py", line 115, in wrapper
    return f(*args, **kwargs)
           ^^^^^^^^^^^^^^^^^^
  File "/home/airflow/.local/lib/python3.12/site-packages/airflow/cli/commands/task_command.py", line 483, in task_run
    task_return_code = _run_task_by_selected_method(args, _dag, ti)
                       ^^^^^^^^^^^^^^^^^^^^^^^^^^^^^^^^^^^^^^^^^^^^
  File "/home/airflow/.local/lib/python3.12/site-packages/airflow/cli/commands/task_command.py", line 256, in _run_task_by_selected_method
    return _run_raw_task(args, ti)
           ^^^^^^^^^^^^^^^^^^^^^^^
  File "/home/airflow/.local/lib/python3.12/site-packages/airflow/cli/commands/task_command.py", line 341, in _run_raw_task
    return ti._run_raw_task(
           ^^^^^^^^^^^^^^^^^
  File "/home/airflow/.local/lib/python3.12/site-packages/airflow/utils/session.py", line 97, in wrapper
    return func(*args, session=session, **kwargs)
           ^^^^^^^^^^^^^^^^^^^^^^^^^^^^^^^^^^^^^^
  File "/home/airflow/.local/lib/python3.12/site-packages/airflow/models/taskinstance.py", line 3004, in _run_raw_task
    return _run_raw_task(
           ^^^^^^^^^^^^^^
  File "/home/airflow/.local/lib/python3.12/site-packages/airflow/models/taskinstance.py", line 273, in _run_raw_task
    TaskInstance._execute_task_with_callbacks(
  File "/home/airflow/.local/lib/python3.12/site-packages/airflow/models/taskinstance.py", line 3158, in _execute_task_with_callbacks
    result = self._execute_task(context, task_orig)
             ^^^^^^^^^^^^^^^^^^^^^^^^^^^^^^^^^^^^^^
  File "/home/airflow/.local/lib/python3.12/site-packages/airflow/models/taskinstance.py", line 3182, in _execute_task
    return _execute_task(self, context, task_orig)
           ^^^^^^^^^^^^^^^^^^^^^^^^^^^^^^^^^^^^^^^
  File "/home/airflow/.local/lib/python3.12/site-packages/airflow/models/taskinstance.py", line 767, in _execute_task
    result = _execute_callable(context=context, **execute_callable_kwargs)
             ^^^^^^^^^^^^^^^^^^^^^^^^^^^^^^^^^^^^^^^^^^^^^^^^^^^^^^^^^^^^^
  File "/home/airflow/.local/lib/python3.12/site-packages/airflow/models/taskinstance.py", line 733, in _execute_callable
    return ExecutionCallableRunner(
           ^^^^^^^^^^^^^^^^^^^^^^^^
  File "/home/airflow/.local/lib/python3.12/site-packages/airflow/utils/operator_helpers.py", line 252, in run
    return self.func(*args, **kwargs)
           ^^^^^^^^^^^^^^^^^^^^^^^^^^
  File "/home/airflow/.local/lib/python3.12/site-packages/airflow/models/baseoperator.py", line 406, in wrapper
    return func(self, *args, **kwargs)
           ^^^^^^^^^^^^^^^^^^^^^^^^^^^
  File "/home/airflow/.local/lib/python3.12/site-packages/airflow/providers/common/sql/operators/sql.py", line 272, in execute
    output = hook.run(
             ^^^^^^^^^
  File "/home/airflow/.local/lib/python3.12/site-packages/airflow/providers/common/sql/hooks/sql.py", line 456, in run
    self._run_command(cur, sql_statement, parameters)
  File "/home/airflow/.local/lib/python3.12/site-packages/airflow/providers/common/sql/hooks/sql.py", line 512, in _run_command
    cur.execute(sql_statement, parameters)
psycopg2.errors.UndefinedTable: relation "table_name" does not exist
LINE 1: INSERT INTO table_name VALUES(7537535, '1ac8a4d459', '2024-1...
                    ^

[2024-10-07T12:57:32.688+0000] {local_task_job_runner.py:266} INFO - Task exited with return code 1
[2024-10-07T12:57:32.702+0000] {taskinstance.py:3900} INFO - 0 downstream tasks scheduled from follow-on schedule check
[2024-10-07T12:57:32.704+0000] {local_task_job_runner.py:245} INFO - ::endgroup::
